
train_translation.py --load=0
Reusing dataset opus_rf (/home/ivlabs/.cache/huggingface/datasets/opus_rf/de-en/1.0.0/3725eb23f8df679ddd37d8d65a6bbfcda7732c66edccbc62a3c3b1354c934c9f)
Some weights of the model checkpoint at bert-base-multilingual-uncased were not used when initializing BertModel: ['cls.predictions.bias', 'cls.predictions.transform.LayerNorm.bias', 'cls.predictions.transform.dense.bias', 'cls.predictions.decoder.weight', 'cls.predictions.transform.dense.weight', 'cls.predictions.transform.LayerNorm.weight', 'cls.seq_relationship.weight', 'cls.seq_relationship.bias']
- This IS expected if you are initializing BertModel from the checkpoint of a model trained on another task or with another architecture (e.g. initializing a BertForSequenceClassification model from a BertForPreTraining model).
- This IS NOT expected if you are initializing BertModel from the checkpoint of a model that you expect to be exactly identical (initializing a BertForSequenceClassification model from a BertForSequenceClassification model).
{"epoch": 0, "step": 0, "loss": 7.121065616607666, "time": 9}
{"epoch": 0, "step": 5, "loss": 97.44178771972656, "time": 10}
/home/ivlabs/context_enhancement/context_new/new/context_enhancement/train_translation.py:275: UserWarning: torch.nn.utils.clip_grad_norm is now deprecated in favor of torch.nn.utils.clip_grad_norm_.
  torch.nn.utils.clip_grad_norm(model.parameters(), args.clip)
{"epoch": 0, "step": 10, "loss": 168.33328247070312, "time": 12}
{"epoch": 0, "step": 15, "loss": 133.17933654785156, "time": 12}
{"epoch": 0, "step": 20, "loss": 112.3768539428711, "time": 13}
{"epoch": 0, "step": 25, "loss": 120.29653930664062, "time": 14}
{"epoch": 0, "step": 30, "loss": 119.97941589355469, "time": 15}
{"epoch": 0, "step": 35, "loss": 86.40515899658203, "time": 16}
{"epoch": 0, "step": 40, "loss": 70.5906982421875, "time": 17}
translation model saved in checkpoint
Exception in thread Thread-3:
Traceback (most recent call last):
  File "/home/ivlabs/miniconda3/envs/ectc/lib/python3.7/threading.py", line 926, in _bootstrap_inner
    self.run()
  File "/home/ivlabs/miniconda3/envs/ectc/lib/python3.7/threading.py", line 870, in run
    self._target(*self._args, **self._kwargs)
  File "/home/ivlabs/miniconda3/envs/ectc/lib/python3.7/site-packages/wandb/sdk/interface/interface.py", line 114, in message_loop
    msg = self._response_queue.get(timeout=1)
  File "/home/ivlabs/miniconda3/envs/ectc/lib/python3.7/multiprocessing/queues.py", line 108, in get
    res = self._recv_bytes()
  File "/home/ivlabs/miniconda3/envs/ectc/lib/python3.7/multiprocessing/connection.py", line 216, in recv_bytes
    buf = self._recv_bytes(maxlength)
  File "/home/ivlabs/miniconda3/envs/ectc/lib/python3.7/multiprocessing/connection.py", line 407, in _recv_bytes
    buf = self._recv(4)
  File "/home/ivlabs/miniconda3/envs/ectc/lib/python3.7/multiprocessing/connection.py", line 383, in _recv
    raise EOFError
EOFError
Thread HandlerThread:
Traceback (most recent call last):
  File "/home/ivlabs/miniconda3/envs/ectc/lib/python3.7/site-packages/wandb/sdk/internal/internal_util.py", line 55, in run
    self._run()
  File "/home/ivlabs/miniconda3/envs/ectc/lib/python3.7/site-packages/wandb/sdk/internal/internal_util.py", line 102, in _run
    record = self._input_record_q.get(timeout=1)
  File "/home/ivlabs/miniconda3/envs/ectc/lib/python3.7/multiprocessing/queues.py", line 108, in get
    res = self._recv_bytes()
  File "/home/ivlabs/miniconda3/envs/ectc/lib/python3.7/multiprocessing/connection.py", line 216, in recv_bytes
    buf = self._recv_bytes(maxlength)
  File "/home/ivlabs/miniconda3/envs/ectc/lib/python3.7/multiprocessing/connection.py", line 407, in _recv_bytes
    buf = self._recv(4)
  File "/home/ivlabs/miniconda3/envs/ectc/lib/python3.7/multiprocessing/connection.py", line 383, in _recv
    raise EOFError
EOFError
[34m[1mwandb[39m[22m: [32m[41mERROR[39m[49m Internal wandb error: file data was not synced
Exception in thread Thread-15:
Traceback (most recent call last):
  File "/home/ivlabs/miniconda3/envs/ectc/lib/python3.7/threading.py", line 926, in _bootstrap_inner
    self.run()
  File "/home/ivlabs/miniconda3/envs/ectc/lib/python3.7/threading.py", line 870, in run
    self._target(*self._args, **self._kwargs)
  File "/home/ivlabs/miniconda3/envs/ectc/lib/python3.7/site-packages/wandb/sdk/wandb_run.py", line 198, in check_status
    status_response = self._interface.communicate_stop_status()
  File "/home/ivlabs/miniconda3/envs/ectc/lib/python3.7/site-packages/wandb/sdk/interface/interface.py", line 743, in communicate_stop_status
    resp = self._communicate(req, timeout=timeout, local=True)
  File "/home/ivlabs/miniconda3/envs/ectc/lib/python3.7/site-packages/wandb/sdk/interface/interface.py", line 545, in _communicate
    return self._communicate_async(rec, local=local).get(timeout=timeout)
  File "/home/ivlabs/miniconda3/envs/ectc/lib/python3.7/site-packages/wandb/sdk/interface/interface.py", line 550, in _communicate_async
    raise Exception("The wandb backend process has shutdown")
Exception: The wandb backend process has shutdown
Traceback (most recent call last):
  File "<string>", line 1, in <module>
  File "/home/ivlabs/miniconda3/envs/ectc/lib/python3.7/multiprocessing/spawn.py", line 105, in spawn_main
    exitcode = _main(fd)
  File "/home/ivlabs/miniconda3/envs/ectc/lib/python3.7/multiprocessing/spawn.py", line 118, in _main
    return self._bootstrap()
  File "/home/ivlabs/miniconda3/envs/ectc/lib/python3.7/multiprocessing/process.py", line 315, in _bootstrap
    threading._shutdown()
  File "/home/ivlabs/miniconda3/envs/ectc/lib/python3.7/threading.py", line 1307, in _shutdown
    lock.acquire()
KeyboardInterrupt