
Reusing dataset opus_rf (/home/ivlabs/.cache/huggingface/datasets/opus_rf/de-en/1.0.0/3725eb23f8df679ddd37d8d65a6bbfcda7732c66edccbc62a3c3b1354c934c9f)
train_translation.py --load 0 --test_translation 1
Reusing dataset opus_rf (/home/ivlabs/.cache/huggingface/datasets/opus_rf/de-en/1.0.0/3725eb23f8df679ddd37d8d65a6bbfcda7732c66edccbc62a3c3b1354c934c9f)
Some weights of the model checkpoint at bert-base-multilingual-uncased were not used when initializing BertModel: ['cls.predictions.transform.LayerNorm.weight', 'cls.seq_relationship.weight', 'cls.predictions.bias', 'cls.seq_relationship.bias', 'cls.predictions.transform.dense.bias', 'cls.predictions.transform.LayerNorm.bias', 'cls.predictions.transform.dense.weight', 'cls.predictions.decoder.weight']
- This IS expected if you are initializing BertModel from the checkpoint of a model trained on another task or with another architecture (e.g. initializing a BertForSequenceClassification model from a BertForPreTraining model).
- This IS NOT expected if you are initializing BertModel from the checkpoint of a model that you expect to be exactly identical (initializing a BertForSequenceClassification model from a BertForSequenceClassification model).
test_bleu_score 0.0
Exception in thread Thread-6:
Traceback (most recent call last):
  File "/home/ivlabs/miniconda3/envs/ectc/lib/python3.7/threading.py", line 926, in _bootstrap_inner
    self.run()
  File "/home/ivlabs/miniconda3/envs/ectc/lib/python3.7/threading.py", line 870, in run
    self._target(*self._args, **self._kwargs)
  File "/home/ivlabs/miniconda3/envs/ectc/lib/python3.7/site-packages/wandb/sdk/interface/interface.py", line 114, in message_loop
    msg = self._response_queue.get(timeout=1)
  File "/home/ivlabs/miniconda3/envs/ectc/lib/python3.7/multiprocessing/queues.py", line 108, in get
    res = self._recv_bytes()
  File "/home/ivlabs/miniconda3/envs/ectc/lib/python3.7/multiprocessing/connection.py", line 216, in recv_bytes
    buf = self._recv_bytes(maxlength)
  File "/home/ivlabs/miniconda3/envs/ectc/lib/python3.7/multiprocessing/connection.py", line 407, in _recv_bytes
    buf = self._recv(4)
  File "/home/ivlabs/miniconda3/envs/ectc/lib/python3.7/multiprocessing/connection.py", line 383, in _recv
    raise EOFError
EOFError
Thread HandlerThread:
Traceback (most recent call last):
  File "/home/ivlabs/miniconda3/envs/ectc/lib/python3.7/site-packages/wandb/sdk/internal/internal_util.py", line 55, in run
    self._run()
  File "/home/ivlabs/miniconda3/envs/ectc/lib/python3.7/site-packages/wandb/sdk/internal/internal_util.py", line 102, in _run
    record = self._input_record_q.get(timeout=1)
  File "/home/ivlabs/miniconda3/envs/ectc/lib/python3.7/multiprocessing/queues.py", line 108, in get
    res = self._recv_bytes()
  File "/home/ivlabs/miniconda3/envs/ectc/lib/python3.7/multiprocessing/connection.py", line 216, in recv_bytes
    buf = self._recv_bytes(maxlength)
  File "/home/ivlabs/miniconda3/envs/ectc/lib/python3.7/multiprocessing/connection.py", line 407, in _recv_bytes
    buf = self._recv(4)
  File "/home/ivlabs/miniconda3/envs/ectc/lib/python3.7/multiprocessing/connection.py", line 383, in _recv
    raise EOFError
EOFError
[34m[1mwandb[39m[22m: [32m[41mERROR[39m[49m Internal wandb error: file data was not synced
Traceback (most recent call last):
  File "<string>", line 1, in <module>
  File "/home/ivlabs/miniconda3/envs/ectc/lib/python3.7/multiprocessing/spawn.py", line 105, in spawn_main
    exitcode = _main(fd)
  File "/home/ivlabs/miniconda3/envs/ectc/lib/python3.7/multiprocessing/spawn.py", line 118, in _main
    return self._bootstrap()
  File "/home/ivlabs/miniconda3/envs/ectc/lib/python3.7/multiprocessing/process.py", line 315, in _bootstrap
    threading._shutdown()
  File "/home/ivlabs/miniconda3/envs/ectc/lib/python3.7/threading.py", line 1307, in _shutdown
    lock.acquire()
KeyboardInterrupt